2021-09-29 10:55:59,983 INFO: Microblog startup [in D:\personal\flask_project\app\__init__.py:45]
2021-09-29 11:17:16,169 INFO: Microblog startup [in D:\personal\flask_project\app\__init__.py:45]
2021-09-29 11:20:48,350 INFO: Microblog startup [in D:\personal\flask_project\app\__init__.py:45]
2021-09-30 09:42:31,399 INFO: Microblog startup [in D:\personal\flask_project\app\__init__.py:48]
2021-09-30 09:44:42,702 INFO: Microblog startup [in D:\personal\flask_project\app\__init__.py:48]
2021-09-30 10:26:23,885 INFO: Microblog startup [in D:\personal\flask_project\app\__init__.py:48]
2021-09-30 10:30:11,029 INFO: Microblog startup [in D:\personal\flask_project\app\__init__.py:48]
2021-09-30 10:31:40,141 INFO: Microblog startup [in D:\personal\flask_project\app\__init__.py:48]
2021-09-30 10:35:07,025 INFO: Microblog startup [in D:\personal\flask_project\app\__init__.py:48]
2021-10-01 10:45:01,785 INFO: Microblog startup [in D:\personal\flask_project\app\__init__.py:50]
2021-10-01 10:45:06,200 ERROR: Exception on / [GET] [in d:\personal\flask_project\venv\lib\site-packages\flask\app.py:1454]
Traceback (most recent call last):
  File "d:\personal\flask_project\venv\lib\site-packages\flask\app.py", line 2070, in wsgi_app
    response = self.full_dispatch_request()
  File "d:\personal\flask_project\venv\lib\site-packages\flask\app.py", line 1515, in full_dispatch_request
    rv = self.handle_user_exception(e)
  File "d:\personal\flask_project\venv\lib\site-packages\flask\app.py", line 1513, in full_dispatch_request
    rv = self.dispatch_request()
  File "d:\personal\flask_project\venv\lib\site-packages\flask\app.py", line 1499, in dispatch_request
    return self.ensure_sync(self.view_functions[rule.endpoint])(**req.view_args)
  File "d:\personal\flask_project\venv\lib\site-packages\flask_login\utils.py", line 272, in decorated_view
    return func(*args, **kwargs)
  File "D:\personal\flask_project\app\routes.py", line 32, in index
    return render_template('index.html', title='Home', form=form,
  File "d:\personal\flask_project\venv\lib\site-packages\flask\templating.py", line 148, in render_template
    ctx.app.jinja_env.get_or_select_template(template_name_or_list),
  File "d:\personal\flask_project\venv\lib\site-packages\jinja2\environment.py", line 1068, in get_or_select_template
    return self.get_template(template_name_or_list, parent, globals)
  File "d:\personal\flask_project\venv\lib\site-packages\jinja2\environment.py", line 997, in get_template
    return self._load_template(name, globals)
  File "d:\personal\flask_project\venv\lib\site-packages\jinja2\environment.py", line 958, in _load_template
    template = self.loader.load(self, name, self.make_globals(globals))
  File "d:\personal\flask_project\venv\lib\site-packages\jinja2\loaders.py", line 137, in load
    code = environment.compile(source, name, filename)
  File "d:\personal\flask_project\venv\lib\site-packages\jinja2\environment.py", line 757, in compile
    self.handle_exception(source=source_hint)
  File "d:\personal\flask_project\venv\lib\site-packages\jinja2\environment.py", line 925, in handle_exception
    raise rewrite_traceback_stack(source=source)
  File "D:\personal\flask_project\app\templates\index.html", line 33, in template
    {% block app_content %}
jinja2.exceptions.TemplateAssertionError: block 'app_content' defined twice
2021-10-01 10:45:34,132 INFO: Microblog startup [in D:\personal\flask_project\app\__init__.py:50]
